2025-05-25 15:23:48.874 WARNING (SyncWorker_0) [homeassistant.loader] We found a custom integration vingcard_allure which has not been tested by Home Assistant. This component might cause stability problems, be sure to disable it if you experience issues with Home Assistant
2025-05-25 15:23:49.785 WARNING (MainThread) [aiohttp_fast_zlib] zlib_ng and isal are not available, falling back to zlib, performance will be degraded.
2025-05-25 15:23:50.778 ERROR (ImportExecutor_0) [homeassistant.components.camera.img_util] Error loading libturbojpeg; Camera snapshot performance will be sub-optimal
Traceback (most recent call last):
  File "/usr/src/app/homeassistant/homeassistant/components/camera/img_util.py", line 100, in __init__
    TurboJPEGSingleton.__instance = TurboJPEG()
                                    ~~~~~~~~~^^
  File "/root/.local/lib/python3.13/site-packages/turbojpeg.py", line 300, in __init__
    self.__find_turbojpeg() if lib_path is None else lib_path)
    ~~~~~~~~~~~~~~~~~~~~~^^
  File "/root/.local/lib/python3.13/site-packages/turbojpeg.py", line 967, in __find_turbojpeg
    raise RuntimeError(
    ...<2 lines>...
        'e.g. jpeg = TurboJPEG(lib_path)')
RuntimeError: Unable to locate turbojpeg library automatically. You may specify the turbojpeg library path manually.
e.g. jpeg = TurboJPEG(lib_path)
2025-05-25 15:23:51.068 ERROR (MainThread) [haffmpeg.core] FFmpeg fails [Errno 2] No such file or directory: 'ffmpeg'
Traceback (most recent call last):
  File "/root/.local/lib/python3.13/site-packages/haffmpeg/core.py", line 130, in open
    self._proc = await asyncio.create_subprocess_exec(
                 ^^^^^^^^^^^^^^^^^^^^^^^^^^^^^^^^^^^^^
    ...<6 lines>...
    )
    ^
  File "/usr/local/lib/python3.13/asyncio/subprocess.py", line 224, in create_subprocess_exec
    transport, protocol = await loop.subprocess_exec(
                          ^^^^^^^^^^^^^^^^^^^^^^^^^^^
    ...<3 lines>...
        stderr=stderr, **kwds)
        ^^^^^^^^^^^^^^^^^^^^^^
  File "/usr/local/lib/python3.13/asyncio/base_events.py", line 1788, in subprocess_exec
    transport = await self._make_subprocess_transport(
                ^^^^^^^^^^^^^^^^^^^^^^^^^^^^^^^^^^^^^^
        protocol, popen_args, False, stdin, stdout, stderr,
        ^^^^^^^^^^^^^^^^^^^^^^^^^^^^^^^^^^^^^^^^^^^^^^^^^^^
        bufsize, **kwargs)
        ^^^^^^^^^^^^^^^^^^
  File "/usr/local/lib/python3.13/asyncio/unix_events.py", line 213, in _make_subprocess_transport
    transp = _UnixSubprocessTransport(self, protocol, args, shell,
                                    stdin, stdout, stderr, bufsize,
                                    waiter=waiter, extra=extra,
                                    **kwargs)
  File "/usr/local/lib/python3.13/asyncio/base_subprocess.py", line 39, in __init__
    self._start(args=args, shell=shell, stdin=stdin, stdout=stdout,
    ~~~~~~~~~~~^^^^^^^^^^^^^^^^^^^^^^^^^^^^^^^^^^^^^^^^^^^^^^^^^^^^
                stderr=stderr, bufsize=bufsize, **kwargs)
                ^^^^^^^^^^^^^^^^^^^^^^^^^^^^^^^^^^^^^^^^^
  File "/usr/local/lib/python3.13/asyncio/unix_events.py", line 855, in _start
    self._proc = subprocess.Popen(
                 ~~~~~~~~~~~~~~~~^
        args, shell=shell, stdin=stdin, stdout=stdout, stderr=stderr,
        ^^^^^^^^^^^^^^^^^^^^^^^^^^^^^^^^^^^^^^^^^^^^^^^^^^^^^^^^^^^^^
        universal_newlines=False, bufsize=bufsize, **kwargs)
        ^^^^^^^^^^^^^^^^^^^^^^^^^^^^^^^^^^^^^^^^^^^^^^^^^^^^
  File "/usr/local/lib/python3.13/subprocess.py", line 1039, in __init__
    self._execute_child(args, executable, preexec_fn, close_fds,
    ~~~~~~~~~~~~~~~~~~~^^^^^^^^^^^^^^^^^^^^^^^^^^^^^^^^^^^^^^^^^
                        pass_fds, cwd, env,
                        ^^^^^^^^^^^^^^^^^^^
    ...<5 lines>...
                        gid, gids, uid, umask,
                        ^^^^^^^^^^^^^^^^^^^^^^
                        start_new_session, process_group)
                        ^^^^^^^^^^^^^^^^^^^^^^^^^^^^^^^^^
  File "/usr/local/lib/python3.13/subprocess.py", line 1969, in _execute_child
    raise child_exception_type(errno_num, err_msg, err_filename)
FileNotFoundError: [Errno 2] No such file or directory: 'ffmpeg'
2025-05-25 15:23:51.082 WARNING (MainThread) [haffmpeg.tools] Error starting FFmpeg.
2025-05-25 15:23:51.457 ERROR (MainThread) [homeassistant.components.sensor] The vingcard_allure platform for the sensor integration does not support platform setup. Please remove it from your config.
2025-05-25 15:23:52.660 ERROR (MainThread) [homeassistant.components.go2rtc] Could not find go2rtc docker binary
2025-05-25 15:23:52.660 ERROR (MainThread) [homeassistant.setup] Setup failed for 'go2rtc': Integration failed to initialize.
2025-05-25 15:23:52.704 ERROR (MainThread) [homeassistant.config_entries] Error importing platform config_flow from integration backup to set up backup configuration entry: Platform backup.config_flow not found
2025-05-25 15:23:52.985 ERROR (MainThread) [homeassistant.setup] Unable to set up dependencies of 'default_config'. Setup failed for dependencies: ['go2rtc']
2025-05-25 15:23:52.985 ERROR (MainThread) [homeassistant.setup] Setup failed for 'default_config': Could not setup dependencies: go2rtc
2025-05-25 15:23:53.672 ERROR (SyncWorker_2) [aiodhcpwatcher] Cannot watch for dhcp packets without a functional packet filter: libpcap is not available. Cannot compile filter !
2025-05-25 15:23:54.711 WARNING (MainThread) [hass_nabucasa.cloud_api] Fetched https://alexa-api.nabucasa.com/access_token (400) 
2025-05-25 15:23:55.124 WARNING (MainThread) [hass_nabucasa.remote] Invalid certificate found for: (inhrktey50p1sg2cvmhi6qeiqqfk4bel.ui.nabu.casa)
2025-05-25 15:26:24.586 ERROR (MainThread) [aiohttp.server] Error handling request
Traceback (most recent call last):
  File "/root/.local/lib/python3.13/site-packages/aiohttp/web_protocol.py", line 380, in data_received
    messages, upgraded, tail = self._request_parser.feed_data(data)
                               ~~~~~~~~~~~~~~~~~~~~~~~~~~~~~~^^^^^^
  File "aiohttp/_http_parser.pyx", line 558, in aiohttp._http_parser.HttpParser.feed_data
aiohttp.http_exceptions.BadHttpMessage: 400, message:
  Data after `Connection: close`:

    b'HELP'
       ^
2025-05-25 15:26:24.730 ERROR (MainThread) [aiohttp.server] Error handling request
Traceback (most recent call last):
  File "/root/.local/lib/python3.13/site-packages/aiohttp/web_protocol.py", line 380, in data_received
    messages, upgraded, tail = self._request_parser.feed_data(data)
                               ~~~~~~~~~~~~~~~~~~~~~~~~~~~~~~^^^^^^
  File "aiohttp/_http_parser.pyx", line 558, in aiohttp._http_parser.HttpParser.feed_data
aiohttp.http_exceptions.BadHttpMessage: 400, message:
  Data after `Connection: close`:

    b'HELP'
       ^
2025-05-25 20:31:30.681 WARNING (MainThread) [hass_nabucasa.iot] Unable to connect: Cannot connect to host cloud.nabucasa.com:443 ssl:default [Domain name not found]
2025-05-25 20:31:35.307 WARNING (MainThread) [hass_nabucasa.iot] Unable to connect: Cannot connect to host cloud.nabucasa.com:443 ssl:default [Domain name not found]
2025-05-25 20:31:52.347 WARNING (MainThread) [hass_nabucasa.iot] Unable to connect: Cannot connect to host cloud.nabucasa.com:443 ssl:default [Domain name not found]
2025-05-25 20:32:07.598 WARNING (MainThread) [homeassistant.helpers.entity] Updating state for binary_sensor.remote_ui (<class 'homeassistant.components.cloud.binary_sensor.CloudRemoteBinary'>) took 1.035 seconds. Please create a bug report at https://github.com/home-assistant/core/issues?q=is%3Aopen+is%3Aissue+label%3A%22integration%3A+cloud%22
2025-05-25 20:32:23.477 WARNING (MainThread) [hass_nabucasa.cloud_api] Fetched https://alexa-api.nabucasa.com/access_token (400) 
2025-05-25 20:32:50.299 ERROR (MainThread) [snitun.multiplexer.core] Ping fails, no response from peer
2025-05-25 20:55:18.555 WARNING (MainThread) [hass_nabucasa.cloud_api] Fetched https://alexa-api.nabucasa.com/access_token (400) 
